try {
  const result = someFunctionThatMayThrowError();
  console.log('Result:', result);
} catch (error) {
  console.error('Error occurred:', error);
}
